Workbook

Sheet Original_Dataset
A1: store_id | B1: month | C1: region | D1: store_type | E1: marketing_spend | F1: footfall | G1: avg_discount_pct | H1: staff_count | I1: inventory_availability_pct | J1: competitor_distance_km | K1: holiday_flag | L1: customer_rating | M1: monthly_sales | N1: monthly_profit
A2: STR-1001 | B2: 45658 | C2: East | D2: Residential | E2: 70389.11 | F2: 8302 | G2: 0.042 | H2: 17 | I2: 75 | J2: 5.28 | K2: 1 | L2: 3.1 | M2: 658832.62 | N2: 84349.93
A3: STR-1001 | B3: 45689 | C3: East | D3: Residential | E3: 43827.89 | F3: 8487 | G3: 0.168 | H3: 23 | I3: 84.4 | J3: 4.31 | K3: 0 | L3: 2.8 | M3: 634436 | N3: 106130.54
A4: STR-1001 | B4: 45717 | C4: East | D4: Residential | E4: 59921.75 | F4: 9113 | G4: 0.133 | H4: 20 | I4: 88 | J4: 12 | K4: 0 | L4: 3.2 | M4: 678722.06 | N4: 101883.86
A5: STR-1001 | B5: 45748 | C5: East | D5: Residential | E5: 56856.63 | F5: 9431 | G5: 0.142 | H5: 23 | I5: 86.9 | J5: 4.97 | K5: 0 | L5: 3.4 | M5: 658920.3 | N5: 97910.37
A6: STR-1002 | B6: 45658 | C6: East | D6: High Street | E6: 48412.64 | F6: 9545 | G6: 0.231 | H6: 21 | I6: 97.6 | J6: 6.94 | K6: 1 | L6: 4.2 | M6: 741341.44 | N6: 119208.17
A7: STR-1002 | B7: 45689 | C7: East | D7: High Street | E7: 64811.21 | F7: 9792 | G7: 0.112 | H7: 20 | I7: 84.2 | J7: 2.88 | K7: 0 | L7: 4.2 | M7: 761835.34 | N7: 149602.23
A8: STR-1002 | B8: 45717 | C8: East | D8: High Street | E8: 46213.45 | F8: 10616 | G8: 0.122 | H8: 22 | I8: 85.2 | J8: 0.2 | K8: 1 | L8: 4.1 | M8: 806615.54 | N8: 131364.62
A9: STR-1002 | B9: 45748 | C9: East | D9: High Street | E9: 68148.52 | F9: 8567 | G9: 0.127 | H9: 23 | I9: 95.6 | J9: 0.8 | K9: 0 | L9: 3.9 | M9: 850164.26 | N9: 149262.75
A10: STR-1003 | B10: 45658 | C10: North | D10: Airport | E10: 71838.86 | F10: 10979 | G10: 0.215 | H10: 26 | I10: 88.6 | J10: 7.7 | K10: 1 | L10: 3.8 | M10: 930581.7 | N10: 136207.98
A11: STR-1003 | B11: 45689 | C11: North | D11: Airport | E11: 68133.44 | F11: 9459 | G11: 0.22 | H11: 21 | I11: 85 | J11: 1.91 | K11: 0 | L11: 4.2 | M11: 779010.94 | N11: 106328.09
A12: STR-1003 | B12: 45717 | C12: North | D12: Airport | E12: 34285.21 | F12: 9172 | G12: 0.213 | H12: 22 | I12: 88.3 | J12: 10.46 | K12: 1 | L12: 3.8 | M12: 723060.76 | N12: 123131.24
A13: STR-1003 | B13: 45748 | C13: North | D13: Airport | E13: 67979.88 | F13: 11230 | G13: 0.002 | H13: 28 | I13: 85.3 | J13: 7.16 | K13: 0 | L13: 3.8 | M13: 910791.94 | N13: 158891.28
... A34: STR-1009 | B34: 45658 | C34: North | D34: Residential | E34: 54597.83 | F34: 9429 | G34: 0.188 | H34: 21 | I34: 83.3 | J34: 11.71 | K34: 0 | L34: 4.2 | M34: 641865.03 | N34: 81342.58
A35: STR-1009 | B35: 45689 | C35: North | D35: Residential | E35: 73771.91 | F35: 11695 | G35: 0.07 | H35: 25 | I35: 84.7 | J35: 0.62 | K35: 0 | M35: 799477.76 | N35: 164974.41
A36: STR-1009 | B36: 45717 | C36: North | D36: Residential | E36: 74413.88 | F36: 9449 | G36: 0.039 | H36: 23 | I36: 92.1 | J36: 2.12 | K36: 0 | L36: 3.5 | M36: 798952.17 | N36: 161499.04
A37: STR-1009 | B37: 45748 | C37: North | D37: Residential | E37: 52483.77 | F37: 10453 | G37: 0.247 | H37: 25 | I37: 99 | J37: 6.31 | K37: 0 | L37: 3.6 | M37: 800979.78 | N37: 149242.27
A38: STR-1010 | B38: 45658 | C38: North | D38: Mall | E38: 75269.87 | F38: 8838 | G38: 0.092 | H38: 21 | I38: 83.1 | J38: 9.56 | K38: 1 | L38: 4.2 | M38: 820593.93 | N38: 115860.06
A39: STR-1010 | B39: 45689 | C39: North | D39: Mall | E39: 61245.41 | F39: 8156 | G39: 0.156 | H39: 19 | I39: 92.9 | J39: 9.05 | K39: 0 | L39: 3.8 | M39: 718330.53 | N39: 93247.9
A40: STR-1010 | B40: 45717 | C40: North | D40: Mall | E40: 93381.26 | F40: 7562 | G40: 0.198 | H40: 19 | I40: 82.9 | J40: 5.05 | K40: 0 | L40: 4 | M40: 736633.4 | N40: 115654.66
A41: STR-1010 | B41: 45748 | C41: North | D41: Mall | E41: 65012.19 | F41: 9598 | G41: 0.085 | H41: 24 | I41: 98.3 | J41: 0.89 | K41: 0 | L41: 3.8 | M41: 828623.85 | N41: 167320.52
A42: STR-1011 | B42: 45658 | C42: East | D42: Mall | E42: 40462.94 | F42: 3660 | G42: 0.218 | H42: 11 | I42: 95.2 | J42: 5.57 | K42: 0 | L42: 4.4 | M42: 592195.85 | N42: 92291.56
A43: STR-1011 | B43: 45689 | C43: East | D43: Mall | E43: 46123.88 | F43: 3227 | G43: 0.143 | H43: 10 | I43: 75.4 | J43: 1.06 | K43: 0 | L43: 4.4 | M43: 532644.46 | N43: 60681.32
A44: STR-1011 | B44: 45717 | C44: East | D44: Mall | E44: 68077.54 | F44: 3360 | G44: 0.128 | H44: 14 | I44: 88.2 | J44: 1.24 | K44: 1 | L44: 4 | M44: 657429.18 | N44: 88919.74
A45: STR-1011 | B45: 45748 | C45: East | D45: Mall | E45: 64882.14 | F45: 3642 | G45: 0.019 | H45: 13 | I45: 87.8 | J45: 4.52 | K45: 0 | L45: 4.2 | M45: 605178 | N45: 106958.74
A46: STR-1012 | B46: 45658 | C46: West | D46: Residential | E46: 138855.51 | F46: 5145 | G46: 0.06 | H46: 17 | I46: 88.2 | J46: 9.58 | K46: 0 | L46: 3.2 | M46: 595467.6 | N46: 104276.46
A47: STR-1012 | B47: 45689 | C47: West | D47: Residential | E47: 63630.21 | F47: 4460 | G47: 0.235 | H47: 14 | I47: 98.6 | J47: 5.52 | K47: 0 | L47: 3.5 | M47: 599603.4 | N47: 112685.12
... A72: STR-1018 | B72: 45717 | C72: East | D72: High Street | E72: 60571.82 | F72: 3193 | G72: 0.197 | H72: 7 | I72: 99 | J72: 1.43 | K72: 0 | L72: 3.2 | M72: 605023.87 | N72: 98545.81
A73: STR-1018 | B73: 45748 | C73: East | D73: High Street | E73: 55081.16 | F73: 5485 | G73: 0.036 | H73: 12 | I73: 88 | K73: 0 | L73: 3.5 | M73: 674774.09 | N73: 141917.59
A74: STR-1019 | B74: 45658 | C74: East | D74: Residential | E74: 46201.46 | F74: 5918 | G74: 0.277 | H74: 13 | I74: 78.8 | J74: 4.91 | K74: 0 | L74: 4.5 | M74: 616069.41 | N74: 54453.99
A75: STR-1019 | B75: 45689 | C75: East | D75: Residential | E75: 53762.92 | F75: 6821 | G75: 0.066 | H75: 19 | I75: 94.6 | J75: 7.03 | K75: 0 | L75: 4.4 | M75: 630829.94 | N75: 117090.02
A76: STR-1019 | B76: 45717 | C76: East | D76: Residential | E76: 70144.78 | F76: 6806 | G76: 0.178 | H76: 20 | I76: 93.1 | J76: 0.28 | K76: 1 | L76: 4.3 | M76: 788087.68 | N76: 116803.42
A77: STR-1019 | B77: 45748 | C77: East | D77: Residential | E77: 58749.63 | F77: 8252 | G77: 0.203 | H77: 20 | I77: 85.2 | J77: 3.61 | K77: 0 | L77: 4.5 | M77: 680840.36 | N77: 68007.68
A78: STR-1020 | B78: 45658 | C78: South | D78: High Street | E78: 56973.18 | F78: 6662 | G78: 0.1 | H78: 15 | I78: 77.7 | J78: 7.52 | K78: 1 | L78: 3.2 | M78: 643657.47 | N78: 87022.45
A79: STR-1020 | B79: 45689 | C79: South | D79: High Street | E79: 54872.82 | F79: 5962 | G79: 0.064 | H79: 12 | I79: 85.4 | J79: 2.58 | K79: 0 | L79: 2.9 | M79: 691112.6 | N79: 109212.83
A80: STR-1020 | B80: 45717 | C80: South | D80: High Street | E80: 80562.81 | F80: 7470 | G80: 0.172 | H80: 16 | I80: 83.5 | J80: 2.29 | K80: 0 | L80: 3.3 | M80: 776922.17 | N80: 150701.93
A81: STR-1020 | B81: 45748 | C81: South | D81: High Street | E81: 77999.9 | F81: 5974 | G81: 0.252 | H81: 14 | I81: 81.3 | J81: 2.39 | K81: 0 | L81: 3.2 | M81: 636561.34 | N81: 93861.06
A82: STR-1021 | B82: 45658 | C82: West | D82: Mall | E82: 60881.01 | F82: 5410 | G82: 0.179 | H82: 15 | I82: 83.9 | J82: 5.24 | K82: 0 | L82: 4.6 | M82: 621369.58 | N82: 85493.64
A83: STR-1021 | B83: 45689 | C83: West | D83: Mall | E83: 60628.38 | F83: 4451 | G83: 0.095 | H83: 10 | I83: 89.6 | J83: 3.17 | K83: 0 | L83: 4.6 | M83: 682208.01 | N83: 110318.84
A84: STR-1021 | B84: 45717 | C84: West | D84: Mall | E84: 72731.14 | F84: 4644 | G84: 0.084 | H84: 15 | I84: 87.1 | J84: 2.66 | K84: 0 | L84: 4.6 | M84: 727241.86 | N84: 155810.3
...

Sheet Cleaned_Data
A1: Cleaned & Prepared Dataset
A2: Missing values in competitor_distance_km and customer_rating are imputed with the column median. All other columns reference Original_Dataset directly.
P3: Median competitor_distance_km | Q3: =MEDIAN(Original_Dataset!J2:J321) -> 3.365
A4: store_id | B4: month | C4: region | D4: store_type | E4: marketing_spend | F4: footfall | G4: avg_discount_pct | H4: staff_count | I4: inventory_availability_pct | J4: competitor_distance_km | K4: holiday_flag | L4: customer_rating | M4: monthly_sales | N4: monthly_profit | P4: Median customer_rating | Q4: =MEDIAN(Original_Dataset!L2:L321) -> 3.9
A5: =Original_Dataset!A2 -> STR-1001 | B5: =Original_Dataset!B2 -> 45658 | C5: =Original_Dataset!C2 -> East | D5: =Original_Dataset!D2 -> Residential | E5: =Original_Dataset!E2 -> 70389.11 | F5: =Original_Dataset!F2 -> 8302 | G5: =Original_Dataset!G2 -> 0.042 | H5: =Original_Dataset!H2 -> 17 | I5: =Original_Dataset!I2 -> 75 | J5: =IF(ISBLANK(Original_Dataset!J2),$Q$3,Original_Dataset!J2) -> 5.28 | K5: =Original_Dataset!K2 -> 1 | L5: =IF(ISBLANK(Original_Dataset!L2),$Q$4,Original_Dataset!L2) -> 3.1 | M5: =Original_Dataset!M2 -> 658832.62 | N5: =Original_Dataset!N2 -> 84349.93
A6: =Original_Dataset!A3 -> STR-1001 | B6: =Original_Dataset!B3 -> 45689 | C6: =Original_Dataset!C3 -> East | D6: =Original_Dataset!D3 -> Residential | E6: =Original_Dataset!E3 -> 43827.89 | F6: =Original_Dataset!F3 -> 8487 | G6: =Original_Dataset!G3 -> 0.168 | H6: =Original_Dataset!H3 -> 23 | I6: =Original_Dataset!I3 -> 84.4 | J6: =IF(ISBLANK(Original_Dataset!J3),$Q$3,Original_Dataset!J3) -> 4.31 | K6: =Original_Dataset!K3 -> 0 | L6: =IF(ISBLANK(Original_Dataset!L3),$Q$4,Original_Dataset!L3) -> 2.8 | M6: =Original_Dataset!M3 -> 634436 | N6: =Original_Dataset!N3 -> 106130.54
A7: =Original_Dataset!A4 -> STR-1001 | B7: =Original_Dataset!B4 -> 45717 | C7: =Original_Dataset!C4 -> East | D7: =Original_Dataset!D4 -> Residential | E7: =Original_Dataset!E4 -> 59921.75 | F7: =Original_Dataset!F4 -> 9113 | G7: =Original_Dataset!G4 -> 0.133 | H7: =Original_Dataset!H4 -> 20 | I7: =Original_Dataset!I4 -> 88 | J7: =IF(ISBLANK(Original_Dataset!J4),$Q$3,Original_Dataset!J4) -> 12 | K7: =Original_Dataset!K4 -> 0 | L7: =IF(ISBLANK(Original_Dataset!L4),$Q$4,Original_Dataset!L4) -> 3.2 | M7: =Original_Dataset!M4 -> 678722.06 | N7: =Original_Dataset!N4 -> 101883.86
A8: =Original_Dataset!A5 -> STR-1001 | B8: =Original_Dataset!B5 -> 45748 | C8: =Original_Dataset!C5 -> East | D8: =Original_Dataset!D5 -> Residential | E8: =Original_Dataset!E5 -> 56856.63 | F8: =Original_Dataset!F5 -> 9431 | G8: =Original_Dataset!G5 -> 0.142 | H8: =Original_Dataset!H5 -> 23 | I8: =Original_Dataset!I5 -> 86.9 | J8: =IF(ISBLANK(Original_Dataset!J5),$Q$3,Original_Dataset!J5) -> 4.97 | K8: =Original_Dataset!K5 -> 0 | L8: =IF(ISBLANK(Original_Dataset!L5),$Q$4,Original_Dataset!L5) -> 3.4 | M8: =Original_Dataset!M5 -> 658920.3 | N8: =Original_Dataset!N5 -> 97910.37
A9: =Original_Dataset!A6 -> STR-1002 | B9: =Original_Dataset!B6 -> 45658 | C9: =Original_Dataset!C6 -> East | D9: =Original_Dataset!D6 -> High Street | E9: =Original_Dataset!E6 -> 48412.64 | F9: =Original_Dataset!F6 -> 9545 | G9: =Original_Dataset!G6 -> 0.231 | H9: =Original_Dataset!H6 -> 21 | I9: =Original_Dataset!I6 -> 97.6 | J9: =IF(ISBLANK(Original_Dataset!J6),$Q$3,Original_Dataset!J6) -> 6.94 | K9: =Original_Dataset!K6 -> 1 | L9: =IF(ISBLANK(Original_Dataset!L6),$Q$4,Original_Dataset!L6) -> 4.2 | M9: =Original_Dataset!M6 -> 741341.44 | N9: =Original_Dataset!N6 -> 119208.17
A10: =Original_Dataset!A7 -> STR-1002 | B10: =Original_Dataset!B7 -> 45689 | C10: =Original_Dataset!C7 -> East | D10: =Original_Dataset!D7 -> High Street | E10: =Original_Dataset!E7 -> 64811.21 | F10: =Original_Dataset!F7 -> 9792 | G10: =Original_Dataset!G7 -> 0.112 | H10: =Original_Dataset!H7 -> 20 | I10: =Original_Dataset!I7 -> 84.2 | J10: =IF(ISBLANK(Original_Dataset!J7),$Q$3,Original_Dataset!J7) -> 2.88 | K10: =Original_Dataset!K7 -> 0 | L10: =IF(ISBLANK(Original_Dataset!L7),$Q$4,Original_Dataset!L7) -> 4.2 | M10: =Original_Dataset!M7 -> 761835.34 | N10: =Original_Dataset!N7 -> 149602.23
A11: =Original_Dataset!A8 -> STR-1002 | B11: =Original_Dataset!B8 -> 45717 | C11: =Original_Dataset!C8 -> East | D11: =Original_Dataset!D8 -> High Street | E11: =Original_Dataset!E8 -> 46213.45 | F11: =Original_Dataset!F8 -> 10616 | G11: =Original_Dataset!G8 -> 0.122 | H11: =Original_Dataset!H8 -> 22 | I11: =Original_Dataset!I8 -> 85.2 | J11: =IF(ISBLANK(Original_Dataset!J8),$Q$3,Original_Dataset!J8) -> 0.2 | K11: =Original_Dataset!K8 -> 1 | L11: =IF(ISBLANK(Original_Dataset!L8),$Q$4,Original_Dataset!L8) -> 4.1 | M11: =Original_Dataset!M8 -> 806615.54 | N11: =Original_Dataset!N8 -> 131364.62
A12: =Original_Dataset!A9 -> STR-1002 | B12: =Original_Dataset!B9 -> 45748 | C12: =Original_Dataset!C9 -> East | D12: =Original_Dataset!D9 -> High Street | E12: =Original_Dataset!E9 -> 68148.52 | F12: =Original_Dataset!F9 -> 8567 | G12: =Original_Dataset!G9 -> 0.127 | H12: =Original_Dataset!H9 -> 23 | I12: =Original_Dataset!I9 -> 95.6 | J12: =IF(ISBLANK(Original_Dataset!J9),$Q$3,Original_Dataset!J9) -> 0.8 | K12: =Original_Dataset!K9 -> 0 | L12: =IF(ISBLANK(Original_Dataset!L9),$Q$4,Original_Dataset!L9) -> 3.9 | M12: =Original_Dataset!M9 -> 850164.26 | N12: =Original_Dataset!N9 -> 149262.75
A13: =Original_Dataset!A10 -> STR-1003 | B13: =Original_Dataset!B10 -> 45658 | C13: =Original_Dataset!C10 -> North | D13: =Original_Dataset!D10 -> Airport | E13: =Original_Dataset!E10 -> 71838.86 | F13: =Original_Dataset!F10 -> 10979 | G13: =Original_Dataset!G10 -> 0.215 | H13: =Original_Dataset!H10 -> 26 | I13: =Original_Dataset!I10 -> 88.6 | J13: =IF(ISBLANK(Original_Dataset!J10),$Q$3,Original_Dataset!J10) -> 7.7 | K13: =Original_Dataset!K10 -> 1 | L13: =IF(ISBLANK(Original_Dataset!L10),$Q$4,Original_Dataset!L10) -> 3.8 | M13: =Original_Dataset!M10 -> 930581.7 | N13: =Original_Dataset!N10 -> 136207.98
A14: =Original_Dataset!A11 -> STR-1003 | B14: =Original_Dataset!B11 -> 45689 | C14: =Original_Dataset!C11 -> North | D14: =Original_Dataset!D11 -> Airport | E14: =Original_Dataset!E11 -> 68133.44 | F14: =Original_Dataset!F11 -> 9459 | G14: =Original_Dataset!G11 -> 0.22 | H14: =Original_Dataset!H11 -> 21 | I14: =Original_Dataset!I11 -> 85 | J14: =IF(ISBLANK(Original_Dataset!J11),$Q$3,Original_Dataset!J11) -> 1.91 | K14: =Original_Dataset!K11 -> 0 | L14: =IF(ISBLANK(Original_Dataset!L11),$Q$4,Original_Dataset!L11) -> 4.2 | M14: =Original_Dataset!M11 -> 779010.94 | N14: =Original_Dataset!N11 -> 106328.09
A15: =Original_Dataset!A12 -> STR-1003 | B15: =Original_Dataset!B12 -> 45717 | C15: =Original_Dataset!C12 -> North | D15: =Original_Dataset!D12 -> Airport | E15: =Original_Dataset!E12 -> 34285.21 | F15: =Original_Dataset!F12 -> 9172 | G15: =Original_Dataset!G12 -> 0.213 | H15: =Original_Dataset!H12 -> 22 | I15: =Original_Dataset!I12 -> 88.3 | J15: =IF(ISBLANK(Original_Dataset!J12),$Q$3,Original_Dataset!J12) -> 10.46 | K15: =Original_Dataset!K12 -> 1 | L15: =IF(ISBLANK(Original_Dataset!L12),$Q$4,Original_Dataset!L12) -> 3.8 | M15: =Original_Dataset!M12 -> 723060.76 | N15: =Original_Dataset!N12 -> 123131.24
A16: =Original_Dataset!A13 -> STR-1003 | B16: =Original_Dataset!B13 -> 45748 | C16: =Original_Dataset!C13 -> North | D16: =Original_Dataset!D13 -> Airport | E16: =Original_Dataset!E13 -> 67979.88 | F16: =Original_Dataset!F13 -> 11230 | G16: =Original_Dataset!G13 -> 0.002 | H16: =Original_Dataset!H13 -> 28 | I16: =Original_Dataset!I13 -> 85.3 | J16: =IF(ISBLANK(Original_Dataset!J13),$Q$3,Original_Dataset!J13) -> 7.16 | K16: =Original_Dataset!K13 -> 0 | L16: =IF(ISBLANK(Original_Dataset!L13),$Q$4,Original_Dataset!L13) -> 3.8 | M16: =Original_Dataset!M13 -> 910791.94 | N16: =Original_Dataset!N13 -> 158891.28
... A324: =Original_Dataset!A321 -> STR-1080 | B324: =Original_Dataset!B321 -> 45748 | C324: =Original_Dataset!C321 -> East | D324: =Original_Dataset!D321 -> Residential | E324: =Original_Dataset!E321 -> 40553.11 | F324: =Original_Dataset!F321 -> 5317 | G324: =Original_Dataset!G321 -> 0.165 | H324: =Original_Dataset!H321 -> 17 | I324: =Original_Dataset!I321 -> 84.3 | J324: =IF(ISBLANK(Original_Dataset!J321),$Q$3,Original_Dataset!J321) -> 11.82 | K324: =Original_Dataset!K321 -> 0 | L324: =IF(ISBLANK(Original_Dataset!L321),$Q$4,Original_Dataset!L321) -> 4.1 | M324: =Original_Dataset!M321 -> 559660.84 | N324: =Original_Dataset!N321 -> 71443.61

Sheet Dummy_Variables
A1: Dummy Variable Creation
A2: store_type reference category = "High Street" (most frequent, 116 of 320 rows). region reference category = "East" (most frequent, 104 of 320 rows). Reference categories are intentionally excluded to avoid the dummy variable trap (perfect multicollinearity).
A4: store_id | B4: month | C4: region | D4: store_type | E4: storetype_Airport | F4: storetype_Mall | G4: storetype_Residential | H4: region_North | I4: region_South | J4: region_West
A5: =Cleaned_Data!A5 -> STR-1001 | B5: =Cleaned_Data!B5 -> 45658 | C5: =Cleaned_Data!C5 -> East | D5: =Cleaned_Data!D5 -> Residential | E5: =IF($D5="Airport",1,0) -> 0 | F5: =IF($D5="Mall",1,0) -> 0 | G5: =IF($D5="Residential",1,0) -> 1 | H5: =IF($C5="North",1,0) -> 0 | I5: =IF($C5="South",1,0) -> 0 | J5: =IF($C5="West",1,0) -> 0
A6: =Cleaned_Data!A6 -> STR-1001 | B6: =Cleaned_Data!B6 -> 45689 | C6: =Cleaned_Data!C6 -> East | D6: =Cleaned_Data!D6 -> Residential | E6: =IF($D6="Airport",1,0) -> 0 | F6: =IF($D6="Mall",1,0) -> 0 | G6: =IF($D6="Residential",1,0) -> 1 | H6: =IF($C6="North",1,0) -> 0 | I6: =IF($C6="South",1,0) -> 0 | J6: =IF($C6="West",1,0) -> 0
A7: =Cleaned_Data!A7 -> STR-1001 | B7: =Cleaned_Data!B7 -> 45717 | C7: =Cleaned_Data!C7 -> East | D7: =Cleaned_Data!D7 -> Residential | E7: =IF($D7="Airport",1,0) -> 0 | F7: =IF($D7="Mall",1,0) -> 0 | G7: =IF($D7="Residential",1,0) -> 1 | H7: =IF($C7="North",1,0) -> 0 | I7: =IF($C7="South",1,0) -> 0 | J7: =IF($C7="West",1,0) -> 0
A8: =Cleaned_Data!A8 -> STR-1001 | B8: =Cleaned_Data!B8 -> 45748 | C8: =Cleaned_Data!C8 -> East | D8: =Cleaned_Data!D8 -> Residential | E8: =IF($D8="Airport",1,0) -> 0 | F8: =IF($D8="Mall",1,0) -> 0 | G8: =IF($D8="Residential",1,0) -> 1 | H8: =IF($C8="North",1,0) -> 0 | I8: =IF($C8="South",1,0) -> 0 | J8: =IF($C8="West",1,0) -> 0
A9: =Cleaned_Data!A9 -> STR-1002 | B9: =Cleaned_Data!B9 -> 45658 | C9: =Cleaned_Data!C9 -> East | D9: =Cleaned_Data!D9 -> High Street | E9: =IF($D9="Airport",1,0) -> 0 | F9: =IF($D9="Mall",1,0) -> 0 | G9: =IF($D9="Residential",1,0) -> 0 | H9: =IF($C9="North",1,0) -> 0 | I9: =IF($C9="South",1,0) -> 0 | J9: =IF($C9="West",1,0) -> 0
A10: =Cleaned_Data!A10 -> STR-1002 | B10: =Cleaned_Data!B10 -> 45689 | C10: =Cleaned_Data!C10 -> East | D10: =Cleaned_Data!D10 -> High Street | E10: =IF($D10="Airport",1,0) -> 0 | F10: =IF($D10="Mall",1,0) -> 0 | G10: =IF($D10="Residential",1,0) -> 0 | H10: =IF($C10="North",1,0) -> 0 | I10: =IF($C10="South",1,0) -> 0 | J10: =IF($C10="West",1,0) -> 0
A11: =Cleaned_Data!A11 -> STR-1002 | B11: =Cleaned_Data!B11 -> 45717 | C11: =Cleaned_Data!C11 -> East | D11: =Cleaned_Data!D11 -> High Street | E11: =IF($D11="Airport",1,0) -> 0 | F11: =IF($D11="Mall",1,0) -> 0 | G11: =IF($D11="Residential",1,0) -> 0 | H11: =IF($C11="North",1,0) -> 0 | I11: =IF($C11="South",1,0) -> 0 | J11: =IF($C11="West",1,0) -> 0
A12: =Cleaned_Data!A12 -> STR-1002 | B12: =Cleaned_Data!B12 -> 45748 | C12: =Cleaned_Data!C12 -> East | D12: =Cleaned_Data!D12 -> High Street | E12: =IF($D12="Airport",1,0) -> 0 | F12: =IF($D12="Mall",1,0) -> 0 | G12: =IF($D12="Residential",1,0) -> 0 | H12: =IF($C12="North",1,0) -> 0 | I12: =IF($C12="South",1,0) -> 0 | J12: =IF($C12="West",1,0) -> 0
A13: =Cleaned_Data!A13 -> STR-1003 | B13: =Cleaned_Data!B13 -> 45658 | C13: =Cleaned_Data!C13 -> North | D13: =Cleaned_Data!D13 -> Airport | E13: =IF($D13="Airport",1,0) -> 1 | F13: =IF($D13="Mall",1,0) -> 0 | G13: =IF($D13="Residential",1,0) -> 0 | H13: =IF($C13="North",1,0) -> 1 | I13: =IF($C13="South",1,0) -> 0 | J13: =IF($C13="West",1,0) -> 0
A14: =Cleaned_Data!A14 -> STR-1003 | B14: =Cleaned_Data!B14 -> 45689 | C14: =Cleaned_Data!C14 -> North | D14: =Cleaned_Data!D14 -> Airport | E14: =IF($D14="Airport",1,0) -> 1 | F14: =IF($D14="Mall",1,0) -> 0 | G14: =IF($D14="Residential",1,0) -> 0 | H14: =IF($C14="North",1,0) -> 1 | I14: =IF($C14="South",1,0) -> 0 | J14: =IF($C14="West",1,0) -> 0
A15: =Cleaned_Data!A15 -> STR-1003 | B15: =Cleaned_Data!B15 -> 45717 | C15: =Cleaned_Data!C15 -> North | D15: =Cleaned_Data!D15 -> Airport | E15: =IF($D15="Airport",1,0) -> 1 | F15: =IF($D15="Mall",1,0) -> 0 | G15: =IF($D15="Residential",1,0) -> 0 | H15: =IF($C15="North",1,0) -> 1 | I15: =IF($C15="South",1,0) -> 0 | J15: =IF($C15="West",1,0) -> 0
A16: =Cleaned_Data!A16 -> STR-1003 | B16: =Cleaned_Data!B16 -> 45748 | C16: =Cleaned_Data!C16 -> North | D16: =Cleaned_Data!D16 -> Airport | E16: =IF($D16="Airport",1,0) -> 1 | F16: =IF($D16="Mall",1,0) -> 0 | G16: =IF($D16="Residential",1,0) -> 0 | H16: =IF($C16="North",1,0) -> 1 | I16: =IF($C16="South",1,0) -> 0 | J16: =IF($C16="West",1,0) -> 0
... A324: =Cleaned_Data!A324 -> STR-1080 | B324: =Cleaned_Data!B324 -> 45748 | C324: =Cleaned_Data!C324 -> East | D324: =Cleaned_Data!D324 -> Residential | E324: =IF($D324="Airport",1,0) -> 0 | F324: =IF($D324="Mall",1,0) -> 0 | G324: =IF($D324="Residential",1,0) -> 1 | H324: =IF($C324="North",1,0) -> 0 | I324: =IF($C324="South",1,0) -> 0 | J324: =IF($C324="West",1,0) -> 0

Sheet Model_Data
A1: Consolidated Model Dataset (numeric predictors + dummy variables, contiguous for regression formulas)
A3: store_id | B3: month | C3: region | D3: store_type | E3: marketing_spend | F3: footfall | G3: avg_discount_pct | H3: staff_count | I3: inventory_availability_pct | J3: competitor_distance_km | K3: holiday_flag | L3: customer_rating | M3: storetype_Airport | N3: storetype_Mall | O3: storetype_Residential | P3: region_North | Q3: region_South | R3: region_West | S3: monthly_sales
A4: =Cleaned_Data!A5 -> STR-1001 | B4: =Cleaned_Data!B5 -> 45658 | C4: =Cleaned_Data!C5 -> East | D4: =Cleaned_Data!D5 -> Residential | E4: =Cleaned_Data!E5 -> 70389.11 | F4: =Cleaned_Data!F5 -> 8302 | G4: =Cleaned_Data!G5 -> 0.042 | H4: =Cleaned_Data!H5 -> 17 | ... L4: =Cleaned_Data!L5 -> 3.1 | M4: =Dummy_Variables!E5 -> 0 | N4: =Dummy_Variables!F5 -> 0 | O4: =Dummy_Variables!G5 -> 1 | P4: =Dummy_Variables!H5 -> 0 | Q4: =Dummy_Variables!I5 -> 0 | R4: =Dummy_Variables!J5 -> 0 | S4: =Cleaned_Data!M5 -> 658832.62
A5: =Cleaned_Data!A6 -> STR-1001 | B5: =Cleaned_Data!B6 -> 45689 | C5: =Cleaned_Data!C6 -> East | D5: =Cleaned_Data!D6 -> Residential | E5: =Cleaned_Data!E6 -> 43827.89 | F5: =Cleaned_Data!F6 -> 8487 | G5: =Cleaned_Data!G6 -> 0.168 | H5: =Cleaned_Data!H6 -> 23 | ... L5: =Cleaned_Data!L6 -> 2.8 | M5: =Dummy_Variables!E6 -> 0 | N5: =Dummy_Variables!F6 -> 0 | O5: =Dummy_Variables!G6 -> 1 | P5: =Dummy_Variables!H6 -> 0 | Q5: =Dummy_Variables!I6 -> 0 | R5: =Dummy_Variables!J6 -> 0 | S5: =Cleaned_Data!M6 -> 634436
A6: =Cleaned_Data!A7 -> STR-1001 | B6: =Cleaned_Data!B7 -> 45717 | C6: =Cleaned_Data!C7 -> East | D6: =Cleaned_Data!D7 -> Residential | E6: =Cleaned_Data!E7 -> 59921.75 | F6: =Cleaned_Data!F7 -> 9113 | G6: =Cleaned_Data!G7 -> 0.133 | H6: =Cleaned_Data!H7 -> 20 | ... L6: =Cleaned_Data!L7 -> 3.2 | M6: =Dummy_Variables!E7 -> 0 | N6: =Dummy_Variables!F7 -> 0 | O6: =Dummy_Variables!G7 -> 1 | P6: =Dummy_Variables!H7 -> 0 | Q6: =Dummy_Variables!I7 -> 0 | R6: =Dummy_Variables!J7 -> 0 | S6: =Cleaned_Data!M7 -> 678722.06
A7: =Cleaned_Data!A8 -> STR-1001 | B7: =Cleaned_Data!B8 -> 45748 | C7: =Cleaned_Data!C8 -> East | D7: =Cleaned_Data!D8 -> Residential | E7: =Cleaned_Data!E8 -> 56856.63 | F7: =Cleaned_Data!F8 -> 9431 | G7: =Cleaned_Data!G8 -> 0.142 | H7: =Cleaned_Data!H8 -> 23 | ... L7: =Cleaned_Data!L8 -> 3.4 | M7: =Dummy_Variables!E8 -> 0 | N7: =Dummy_Variables!F8 -> 0 | O7: =Dummy_Variables!G8 -> 1 | P7: =Dummy_Variables!H8 -> 0 | Q7: =Dummy_Variables!I8 -> 0 | R7: =Dummy_Variables!J8 -> 0 | S7: =Cleaned_Data!M8 -> 658920.3
A8: =Cleaned_Data!A9 -> STR-1002 | B8: =Cleaned_Data!B9 -> 45658 | C8: =Cleaned_Data!C9 -> East | D8: =Cleaned_Data!D9 -> High Street | E8: =Cleaned_Data!E9 -> 48412.64 | F8: =Cleaned_Data!F9 -> 9545 | G8: =Cleaned_Data!G9 -> 0.231 | H8: =Cleaned_Data!H9 -> 21 | ... L8: =Cleaned_Data!L9 -> 4.2 | M8: =Dummy_Variables!E9 -> 0 | N8: =Dummy_Variables!F9 -> 0 | O8: =Dummy_Variables!G9 -> 0 | P8: =Dummy_Variables!H9 -> 0 | Q8: =Dummy_Variables!I9 -> 0 | R8: =Dummy_Variables!J9 -> 0 | S8: =Cleaned_Data!M9 -> 741341.44
A9: =Cleaned_Data!A10 -> STR-1002 | B9: =Cleaned_Data!B10 -> 45689 | C9: =Cleaned_Data!C10 -> East | D9: =Cleaned_Data!D10 -> High Street | E9: =Cleaned_Data!E10 -> 64811.21 | F9: =Cleaned_Data!F10 -> 9792 | G9: =Cleaned_Data!G10 -> 0.112 | H9: =Cleaned_Data!H10 -> 20 | ... L9: =Cleaned_Data!L10 -> 4.2 | M9: =Dummy_Variables!E10 -> 0 | N9: =Dummy_Variables!F10 -> 0 | O9: =Dummy_Variables!G10 -> 0 | P9: =Dummy_Variables!H10 -> 0 | Q9: =Dummy_Variables!I10 -> 0 | R9: =Dummy_Variables!J10 -> 0 | S9: =Cleaned_Data!M10 -> 761835.34
A10: =Cleaned_Data!A11 -> STR-1002 | B10: =Cleaned_Data!B11 -> 45717 | C10: =Cleaned_Data!C11 -> East | D10: =Cleaned_Data!D11 -> High Street | E10: =Cleaned_Data!E11 -> 46213.45 | F10: =Cleaned_Data!F11 -> 10616 | G10: =Cleaned_Data!G11 -> 0.122 | H10: =Cleaned_Data!H11 -> 22 | ... L10: =Cleaned_Data!L11 -> 4.1 | M10: =Dummy_Variables!E11 -> 0 | N10: =Dummy_Variables!F11 -> 0 | O10: =Dummy_Variables!G11 -> 0 | P10: =Dummy_Variables!H11 -> 0 | Q10: =Dummy_Variables!I11 -> 0 | R10: =Dummy_Variables!J11 -> 0 | S10: =Cleaned_Data!M11 -> 806615.54
A11: =Cleaned_Data!A12 -> STR-1002 | B11: =Cleaned_Data!B12 -> 45748 | C11: =Cleaned_Data!C12 -> East | D11: =Cleaned_Data!D12 -> High Street | E11: =Cleaned_Data!E12 -> 68148.52 | F11: =Cleaned_Data!F12 -> 8567 | G11: =Cleaned_Data!G12 -> 0.127 | H11: =Cleaned_Data!H12 -> 23 | ... L11: =Cleaned_Data!L12 -> 3.9 | M11: =Dummy_Variables!E12 -> 0 | N11: =Dummy_Variables!F12 -> 0 | O11: =Dummy_Variables!G12 -> 0 | P11: =Dummy_Variables!H12 -> 0 | Q11: =Dummy_Variables!I12 -> 0 | R11: =Dummy_Variables!J12 -> 0 | S11: =Cleaned_Data!M12 -> 850164.26
A12: =Cleaned_Data!A13 -> STR-1003 | B12: =Cleaned_Data!B13 -> 45658 | C12: =Cleaned_Data!C13 -> North | D12: =Cleaned_Data!D13 -> Airport | E12: =Cleaned_Data!E13 -> 71838.86 | F12: =Cleaned_Data!F13 -> 10979 | G12: =Cleaned_Data!G13 -> 0.215 | H12: =Cleaned_Data!H13 -> 26 | ... L12: =Cleaned_Data!L13 -> 3.8 | M12: =Dummy_Variables!E13 -> 1 | N12: =Dummy_Variables!F13 -> 0 | O12: =Dummy_Variables!G13 -> 0 | P12: =Dummy_Variables!H13 -> 1 | Q12: =Dummy_Variables!I13 -> 0 | R12: =Dummy_Variables!J13 -> 0 | S12: =Cleaned_Data!M13 -> 930581.7
A13: =Cleaned_Data!A14 -> STR-1003 | B13: =Cleaned_Data!B14 -> 45689 | C13: =Cleaned_Data!C14 -> North | D13: =Cleaned_Data!D14 -> Airport | E13: =Cleaned_Data!E14 -> 68133.44 | F13: =Cleaned_Data!F14 -> 9459 | G13: =Cleaned_Data!G14 -> 0.22 | H13: =Cleaned_Data!H14 -> 21 | ... L13: =Cleaned_Data!L14 -> 4.2 | M13: =Dummy_Variables!E14 -> 1 | N13: =Dummy_Variables!F14 -> 0 | O13: =Dummy_Variables!G14 -> 0 | P13: =Dummy_Variables!H14 -> 1 | Q13: =Dummy_Variables!I14 -> 0 | R13: =Dummy_Variables!J14 -> 0 | S13: =Cleaned_Data!M14 -> 779010.94
A14: =Cleaned_Data!A15 -> STR-1003 | B14: =Cleaned_Data!B15 -> 45717 | C14: =Cleaned_Data!C15 -> North | D14: =Cleaned_Data!D15 -> Airport | E14: =Cleaned_Data!E15 -> 34285.21 | F14: =Cleaned_Data!F15 -> 9172 | G14: =Cleaned_Data!G15 -> 0.213 | H14: =Cleaned_Data!H15 -> 22 | ... L14: =Cleaned_Data!L15 -> 3.8 | M14: =Dummy_Variables!E15 -> 1 | N14: =Dummy_Variables!F15 -> 0 | O14: =Dummy_Variables!G15 -> 0 | P14: =Dummy_Variables!H15 -> 1 | Q14: =Dummy_Variables!I15 -> 0 | R14: =Dummy_Variables!J15 -> 0 | S14: =Cleaned_Data!M15 -> 723060.76
A15: =Cleaned_Data!A16 -> STR-1003 | B15: =Cleaned_Data!B16 -> 45748 | C15: =Cleaned_Data!C16 -> North | D15: =Cleaned_Data!D16 -> Airport | E15: =Cleaned_Data!E16 -> 67979.88 | F15: =Cleaned_Data!F16 -> 11230 | G15: =Cleaned_Data!G16 -> 0.002 | H15: =Cleaned_Data!H16 -> 28 | ... L15: =Cleaned_Data!L16 -> 3.8 | M15: =Dummy_Variables!E16 -> 1 | N15: =Dummy_Variables!F16 -> 0 | O15: =Dummy_Variables!G16 -> 0 | P15: =Dummy_Variables!H16 -> 1 | Q15: =Dummy_Variables!I16 -> 0 | R15: =Dummy_Variables!J16 -> 0 | S15: =Cleaned_Data!M16 -> 910791.94
... A323: =Cleaned_Data!A324 -> STR-1080 | B323: =Cleaned_Data!B324 -> 45748 | C323: =Cleaned_Data!C324 -> East | D323: =Cleaned_Data!D324 -> Residential | E323: =Cleaned_Data!E324 -> 40553.11 | F323: =Cleaned_Data!F324 -> 5317 | G323: =Cleaned_Data!G324 -> 0.165 | H323: =Cleaned_Data!H324 -> 17 | ... L323: =Cleaned_Data!L324 -> 4.1 | M323: =Dummy_Variables!E324 -> 0 | N323: =Dummy_Variables!F324 -> 0 | O323: =Dummy_Variables!G324 -> 1 | P323: =Dummy_Variables!H324 -> 0 | Q323: =Dummy_Variables!I324 -> 0 | R323: =Dummy_Variables!J324 -> 0 | S323: =Cleaned_Data!M324 -> 559660.84

Sheet Simple_Regression
A1: Simple Linear Regression Models (monthly_sales as dependent variable)
A3: Model A: monthly_sales ~ marketing_spend
A4: Raw LINEST array (reference only) — see computed labels below for slope/intercept/R2/etc.
B5: =INDEX(LINEST(Model_Data!S4:S323,Model_Data!E4:E323,TRUE(),TRUE()),1,1) -> 2.1295753
A11: Slope (coefficient) | B11: =INDEX(LINEST(Model_Data!S4:S323,Model_Data!E4:E323,TRUE(),TRUE()),1,1) -> 2.1295753
A12: Intercept | B12: =INDEX(LINEST(Model_Data!S4:S323,Model_Data!E4:E323,TRUE(),TRUE()),1,2) -> 560777.35
A13: Std Error of Slope | B13: =INDEX(LINEST(Model_Data!S4:S323,Model_Data!E4:E323,TRUE(),TRUE()),2,1) -> 0.26647838
A14: R-squared | B14: =INDEX(LINEST(Model_Data!S4:S323,Model_Data!E4:E323,TRUE(),TRUE()),3,1) -> 0.16724469
A15: F-statistic | B15: =INDEX(LINEST(Model_Data!S4:S323,Model_Data!E4:E323,TRUE(),TRUE()),4,1) -> 63.864873
A16: Degrees of Freedom | B16: =INDEX(LINEST(Model_Data!S4:S323,Model_Data!E4:E323,TRUE(),TRUE()),4,2) -> 318
A17: t-stat (slope) | B17: =INDEX(LINEST(Model_Data!S4:S323,Model_Data!E4:E323,TRUE(),TRUE()),1,1)/INDEX(LINEST(Model_Data!S4:S323,Model_Data!E4:E323,TRUE(),TRUE()),2,1) -> 7.9915501
A18: P-value (slope) | B18: =TDIST(ABS(INDEX(LINEST(Model_Data!S4:S323,Model_Data!E4:E323,TRUE(),TRUE()),1,1)/INDEX(LINEST(Model_Data!S4:S323,Model_Data!E4:E323,TRUE(),TRUE()),2,1)),INDEX(LINEST(Model_Data!S4:S323,Model_Data!E4:E323,TRUE(),TRUE()),4,2),2) -> 2.4800615e-14
A21: Model B: monthly_sales ~ footfall
A22: Raw LINEST array (reference only) — see computed labels below for slope/intercept/R2/etc.
B23: =INDEX(LINEST(Model_Data!S4:S323,Model_Data!F4:F323,TRUE(),TRUE()),1,1) -> 35.678031
A29: Slope (coefficient) | B29: =INDEX(LINEST(Model_Data!S4:S323,Model_Data!F4:F323,TRUE(),TRUE()),1,1) -> 35.678031
A30: Intercept | B30: =INDEX(LINEST(Model_Data!S4:S323,Model_Data!F4:F323,TRUE(),TRUE()),1,2) -> 446410.58
A31: Std Error of Slope | B31: =INDEX(LINEST(Model_Data!S4:S323,Model_Data!F4:F323,TRUE(),TRUE()),2,1) -> 1.1973783
A32: R-squared | B32: =INDEX(LINEST(Model_Data!S4:S323,Model_Data!F4:F323,TRUE(),TRUE()),3,1) -> 0.73628534
A33: F-statistic | B33: =INDEX(LINEST(Model_Data!S4:S323,Model_Data!F4:F323,TRUE(),TRUE()),4,1) -> 887.84878
A34: Degrees of Freedom | B34: =INDEX(LINEST(Model_Data!S4:S323,Model_Data!F4:F323,TRUE(),TRUE()),4,2) -> 318
A35: t-stat (slope) | B35: =INDEX(LINEST(Model_Data!S4:S323,Model_Data!F4:F323,TRUE(),TRUE()),1,1)/INDEX(LINEST(Model_Data!S4:S323,Model_Data!F4:F323,TRUE(),TRUE()),2,1) -> 29.796791
A36: P-value (slope) | B36: =TDIST(ABS(INDEX(LINEST(Model_Data!S4:S323,Model_Data!F4:F323,TRUE(),TRUE()),1,1)/INDEX(LINEST(Model_Data!S4:S323,Model_Data!F4:F323,TRUE(),TRUE()),2,1)),INDEX(LINEST(Model_Data!S4:S323,Model_Data!F4:F323,TRUE(),TRUE()),4,2),2) -> 4.7503615e-94
A39: Model C: monthly_sales ~ avg_discount_pct
A40: Raw LINEST array (reference only) — see computed labels below for slope/intercept/R2/etc.
B41: =INDEX(LINEST(Model_Data!S4:S323,Model_Data!G4:G323,TRUE(),TRUE()),1,1) -> -138730.45
A47: Slope (coefficient) | B47: =INDEX(LINEST(Model_Data!S4:S323,Model_Data!G4:G323,TRUE(),TRUE()),1,1) -> -138730.45
A48: Intercept | B48: =INDEX(LINEST(Model_Data!S4:S323,Model_Data!G4:G323,TRUE(),TRUE()),1,2) -> 697835.63
A49: Std Error of Slope | B49: =INDEX(LINEST(Model_Data!S4:S323,Model_Data!G4:G323,TRUE(),TRUE()),2,1) -> 85086.38
A50: R-squared | B50: =INDEX(LINEST(Model_Data!S4:S323,Model_Data!G4:G323,TRUE(),TRUE()),3,1) -> 0.008290503
A51: F-statistic | B51: =INDEX(LINEST(Model_Data!S4:S323,Model_Data!G4:G323,TRUE(),TRUE()),4,1) -> 2.6584196
A52: Degrees of Freedom | B52: =INDEX(LINEST(Model_Data!S4:S323,Model_Data!G4:G323,TRUE(),TRUE()),4,2) -> 318
A53: t-stat (slope) | B53: =INDEX(LINEST(Model_Data!S4:S323,Model_Data!G4:G323,TRUE(),TRUE()),1,1)/INDEX(LINEST(Model_Data!S4:S323,Model_Data!G4:G323,TRUE(),TRUE()),2,1) -> -1.6304661
A54: P-value (slope) | B54: =TDIST(ABS(INDEX(LINEST(Model_Data!S4:S323,Model_Data!G4:G323,TRUE(),TRUE()),1,1)/INDEX(LINEST(Model_Data!S4:S323,Model_Data!G4:G323,TRUE(),TRUE()),2,1)),INDEX(LINEST(Model_Data!S4:S323,Model_Data!G4:G323,TRUE(),TRUE()),4,2),2) -> 0.10399305
A57: Model D: monthly_sales ~ inventory_availability_pct
A58: Raw LINEST array (reference only) — see computed labels below for slope/intercept/R2/etc.
B59: =INDEX(LINEST(Model_Data!S4:S323,Model_Data!I4:I323,TRUE(),TRUE()),1,1) -> 2217.8319
A65: Slope (coefficient) | B65: =INDEX(LINEST(Model_Data!S4:S323,Model_Data!I4:I323,TRUE(),TRUE()),1,1) -> 2217.8319
A66: Intercept | B66: =INDEX(LINEST(Model_Data!S4:S323,Model_Data!I4:I323,TRUE(),TRUE()),1,2) -> 484814.26
A67: Std Error of Slope | B67: =INDEX(LINEST(Model_Data!S4:S323,Model_Data!I4:I323,TRUE(),TRUE()),2,1) -> 1078.8571
...

Sheet Multiple_Regression
A1: Multiple Linear Regression Model
A2: Predictors: footfall, marketing_spend, inventory_availability_pct, avg_discount_pct, storetype_Airport, storetype_Mall, storetype_Residential (reference: High Street). Dependent variable: monthly_sales.
A4: footfall | B4: marketing_spend | C4: inventory_availability_pct | D4: avg_discount_pct | E4: storetype_Airport | F4: storetype_Mall | G4: storetype_Residential | H4: monthly_sales | K4: LINEST Output
A5: =Model_Data!F4 -> 8302 | B5: =Model_Data!E4 -> 70389.11 | C5: =Model_Data!I4 -> 75 | D5: =Model_Data!G4 -> 0.042 | E5: =Model_Data!M4 -> 0 | F5: =Model_Data!N4 -> 0 | G5: =Model_Data!O4 -> 1 | H5: =Model_Data!S4 -> 658832.62 | K5: Raw LINEST slope (reference only) — see computed labels below for full coefficient table.
A6: =Model_Data!F5 -> 8487 | B6: =Model_Data!E5 -> 43827.89 | C6: =Model_Data!I5 -> 84.4 | D6: =Model_Data!G5 -> 0.168 | E6: =Model_Data!M5 -> 0 | F6: =Model_Data!N5 -> 0 | G6: =Model_Data!O5 -> 1 | H6: =Model_Data!S5 -> 634436 | K6: =INDEX(LINEST(H5:H324,A5:G324,TRUE(),TRUE()),1,1) -> -16575.848
A7: =Model_Data!F6 -> 9113 | B7: =Model_Data!E6 -> 59921.75 | C7: =Model_Data!I6 -> 88 | D7: =Model_Data!G6 -> 0.133 | E7: =Model_Data!M6 -> 0 | F7: =Model_Data!N6 -> 0 | G7: =Model_Data!O6 -> 1 | H7: =Model_Data!S6 -> 678722.06
A8: =Model_Data!F7 -> 9431 | B8: =Model_Data!E7 -> 56856.63 | C8: =Model_Data!I7 -> 86.9 | D8: =Model_Data!G7 -> 0.142 | E8: =Model_Data!M7 -> 0 | F8: =Model_Data!N7 -> 0 | G8: =Model_Data!O7 -> 1 | H8: =Model_Data!S7 -> 658920.3
A9: =Model_Data!F8 -> 9545 | B9: =Model_Data!E8 -> 48412.64 | C9: =Model_Data!I8 -> 97.6 | D9: =Model_Data!G8 -> 0.231 | E9: =Model_Data!M8 -> 0 | F9: =Model_Data!N8 -> 0 | G9: =Model_Data!O8 -> 0 | H9: =Model_Data!S8 -> 741341.44
A10: =Model_Data!F9 -> 9792 | B10: =Model_Data!E9 -> 64811.21 | C10: =Model_Data!I9 -> 84.2 | D10: =Model_Data!G9 -> 0.112 | E10: =Model_Data!M9 -> 0 | F10: =Model_Data!N9 -> 0 | G10: =Model_Data!O9 -> 0 | H10: =Model_Data!S9 -> 761835.34
A11: =Model_Data!F10 -> 10616 | B11: =Model_Data!E10 -> 46213.45 | C11: =Model_Data!I10 -> 85.2 | D11: =Model_Data!G10 -> 0.122 | E11: =Model_Data!M10 -> 0 | F11: =Model_Data!N10 -> 0 | G11: =Model_Data!O10 -> 0 | H11: =Model_Data!S10 -> 806615.54 | K11: Variable | L11: Coefficient | M11: Std Error | N11: t-stat | O11: P-value
A12: =Model_Data!F11 -> 8567 | B12: =Model_Data!E11 -> 68148.52 | C12: =Model_Data!I11 -> 95.6 | D12: =Model_Data!G11 -> 0.127 | E12: =Model_Data!M11 -> 0 | F12: =Model_Data!N11 -> 0 | G12: =Model_Data!O11 -> 0 | H12: =Model_Data!S11 -> 850164.26 | K12: Intercept | L12: =INDEX(LINEST(H5:H324,A5:G324,TRUE(),TRUE()),1,8) -> 136913.65 | M12: =INDEX(LINEST(H5:H324,A5:G324,TRUE(),TRUE()),2,8) -> 43429.51 | N12: =L12/M12 -> 3.1525487 | O12: =TDIST(ABS(N12),INDEX(LINEST(H5:H324,A5:G324,TRUE(),TRUE()),4,2),2) -> 0.0017758246
A13: =Model_Data!F12 -> 10979 | B13: =Model_Data!E12 -> 71838.86 | C13: =Model_Data!I12 -> 88.6 | D13: =Model_Data!G12 -> 0.215 | E13: =Model_Data!M12 -> 1 | F13: =Model_Data!N12 -> 0 | G13: =Model_Data!O12 -> 0 | H13: =Model_Data!S12 -> 930581.7 | K13: footfall (coef) | L13: =INDEX(LINEST(H5:H324,A5:G324,TRUE(),TRUE()),1,7) -> 33.664405 | M13: =INDEX(LINEST(H5:H324,A5:G324,TRUE(),TRUE()),2,7) -> 1.0308343 | N13: =L13/M13 -> 32.657435 | O13: =TDIST(ABS(N13),INDEX(LINEST(H5:H324,A5:G324,TRUE(),TRUE()),4,2),2) -> 1.1222697e-102
A14: =Model_Data!F13 -> 9459 | B14: =Model_Data!E13 -> 68133.44 | C14: =Model_Data!I13 -> 85 | D14: =Model_Data!G13 -> 0.22 | E14: =Model_Data!M13 -> 1 | F14: =Model_Data!N13 -> 0 | G14: =Model_Data!O13 -> 0 | H14: =Model_Data!S13 -> 779010.94 | K14: marketing_spend (coef) | L14: =INDEX(LINEST(H5:H324,A5:G324,TRUE(),TRUE()),1,6) -> 1.1654929 | M14: =INDEX(LINEST(H5:H324,A5:G324,TRUE(),TRUE()),2,6) -> 0.12848737 | N14: =L14/M14 -> 9.0708754 | O14: =TDIST(ABS(N14),INDEX(LINEST(H5:H324,A5:G324,TRUE(),TRUE()),4,2),2) -> 1.3555461e-17
A15: =Model_Data!F14 -> 9172 | B15: =Model_Data!E14 -> 34285.21 | C15: =Model_Data!I14 -> 88.3 | D15: =Model_Data!G14 -> 0.213 | E15: =Model_Data!M14 -> 1 | F15: =Model_Data!N14 -> 0 | G15: =Model_Data!O14 -> 0 | H15: =Model_Data!S14 -> 723060.76 | K15: inventory_availability_pct (coef) | L15: =INDEX(LINEST(H5:H324,A5:G324,TRUE(),TRUE()),1,5) -> 3001.1957 | M15: =INDEX(LINEST(H5:H324,A5:G324,TRUE(),TRUE()),2,5) -> 466.59755 | N15: =L15/M15 -> 6.4320862 | O15: =TDIST(ABS(N15),INDEX(LINEST(H5:H324,A5:G324,TRUE(),TRUE()),4,2),2) -> 4.7245685e-10
A16: =Model_Data!F15 -> 11230 | B16: =Model_Data!E15 -> 67979.88 | C16: =Model_Data!I15 -> 85.3 | D16: =Model_Data!G15 -> 0.002 | E16: =Model_Data!M15 -> 1 | F16: =Model_Data!N15 -> 0 | G16: =Model_Data!O15 -> 0 | H16: =Model_Data!S15 -> 910791.94 | K16: avg_discount_pct (coef) | L16: =INDEX(LINEST(H5:H324,A5:G324,TRUE(),TRUE()),1,4) -> -58920.807 | M16: =INDEX(LINEST(H5:H324,A5:G324,TRUE(),TRUE()),2,4) -> 36743.021 | N16: =L16/M16 -> -1.6035918 | O16: =TDIST(ABS(N16),INDEX(LINEST(H5:H324,A5:G324,TRUE(),TRUE()),4,2),2) -> 0.10981586
A17: =Model_Data!F16 -> 12775 | B17: =Model_Data!E16 -> 71828.26 | C17: =Model_Data!I16 -> 81.7 | D17: =Model_Data!G16 -> 0.116 | E17: =Model_Data!M16 -> 0 | F17: =Model_Data!N16 -> 0 | G17: =Model_Data!O16 -> 1 | H17: =Model_Data!S16 -> 922168.6 | K17: storetype_Airport (coef) | L17: =INDEX(LINEST(H5:H324,A5:G324,TRUE(),TRUE()),1,3) -> 21905.715 | M17: =INDEX(LINEST(H5:H324,A5:G324,TRUE(),TRUE()),2,3) -> 9402.0876 | N17: =L17/M17 -> 2.3298777 | O17: =TDIST(ABS(N17),INDEX(LINEST(H5:H324,A5:G324,TRUE(),TRUE()),4,2),2) -> 0.020450265
A18: =Model_Data!F17 -> 10054 | B18: =Model_Data!E17 -> 55716.82 | C18: =Model_Data!I17 -> 84.9 | D18: =Model_Data!G17 -> 0.146 | E18: =Model_Data!M17 -> 0 | F18: =Model_Data!N17 -> 0 | G18: =Model_Data!O17 -> 1 | H18: =Model_Data!S17 -> 726606.28 | K18: storetype_Mall (coef) | L18: =INDEX(LINEST(H5:H324,A5:G324,TRUE(),TRUE()),1,2) -> 11433.464 | M18: =INDEX(LINEST(H5:H324,A5:G324,TRUE(),TRUE()),2,2) -> 6578.0772 | N18: =L18/M18 -> 1.7381164 | O18: =TDIST(ABS(N18),INDEX(LINEST(H5:H324,A5:G324,TRUE(),TRUE()),4,2),2) -> 0.083176903
A19: =Model_Data!F18 -> 8895 | B19: =Model_Data!E18 -> 59909.51 | C19: =Model_Data!I18 -> 88.8 | D19: =Model_Data!G18 -> 0.228 | E19: =Model_Data!M18 -> 0 | F19: =Model_Data!N18 -> 0 | G19: =Model_Data!O18 -> 1 | H19: =Model_Data!S18 -> 746501.09 | K19: storetype_Residential (coef) | L19: =INDEX(LINEST(H5:H324,A5:G324,TRUE(),TRUE()),1,1) -> -16575.848 | M19: =INDEX(LINEST(H5:H324,A5:G324,TRUE(),TRUE()),2,1) -> 6085.6267 | N19: =L19/M19 -> -2.7237701 | O19: =TDIST(ABS(N19),INDEX(LINEST(H5:H324,A5:G324,TRUE(),TRUE()),4,2),2) -> 0.0068177238
A20: =Model_Data!F19 -> 10940 | B20: =Model_Data!E19 -> 75305.71 | C20: =Model_Data!I19 -> 76.5 | D20: =Model_Data!G19 -> 0.006 | E20: =Model_Data!M19 -> 0 | F20: =Model_Data!N19 -> 0 | G20: =Model_Data!O19 -> 1 | H20: =Model_Data!S19 -> 834017.02
A21: =Model_Data!F20 -> 7057 | B21: =Model_Data!E20 -> 48804.22 | C21: =Model_Data!I20 -> 87.7 | D21: =Model_Data!G20 -> 0.005 | E21: =Model_Data!M20 -> 0 | F21: =Model_Data!N20 -> 0 | G21: =Model_Data!O20 -> 1 | H21: =Model_Data!S20 -> 666152.52 | K21: R-squared | L21: =INDEX(LINEST(H5:H324,A5:G324,TRUE(),TRUE()),3,1) -> 0.82139228
A22: =Model_Data!F21 -> 4263 | B22: =Model_Data!E21 -> 59117.9 | C22: =Model_Data!I21 -> 87.6 | D22: =Model_Data!G21 -> 0.119 | E22: =Model_Data!M21 -> 0 | F22: =Model_Data!N21 -> 0 | G22: =Model_Data!O21 -> 1 | H22: =Model_Data!S21 -> 573155.19 | K22: F-statistic | L22: =INDEX(LINEST(H5:H324,A5:G324,TRUE(),TRUE()),4,1) -> 204.97785
A23: =Model_Data!F22 -> 5538 | B23: =Model_Data!E22 -> 78831.12 | C23: =Model_Data!I22 -> 94.1 | D23: =Model_Data!G22 -> 0 | E23: =Model_Data!M22 -> 0 | F23: =Model_Data!N22 -> 0 | G23: =Model_Data!O22 -> 1 | H23: =Model_Data!S22 -> 666573.2 | K23: Degrees of Freedom (resid) | L23: =INDEX(LINEST(H5:H324,A5:G324,TRUE(),TRUE()),4,2) -> 312
A24: =Model_Data!F23 -> 4865 | B24: =Model_Data!E23 -> 41441.93 | C24: =Model_Data!I23 -> 88.3 | D24: =Model_Data!G23 -> 0.158 | E24: =Model_Data!M23 -> 0 | F24: =Model_Data!N23 -> 0 | G24: =Model_Data!O23 -> 1 | H24: =Model_Data!S23 -> 591619.95 | K24: N (observations) | L24: =COUNT(H5:H324) -> 320
A25: =Model_Data!F24 -> 2822 | B25: =Model_Data!E24 -> 30356.28 | C25: =Model_Data!I24 -> 84.8 | D25: =Model_Data!G24 -> 0.231 | E25: =Model_Data!M24 -> 0 | F25: =Model_Data!N24 -> 0 | G25: =Model_Data!O24 -> 1 | H25: =Model_Data!S24 -> 415721.82
A26: =Model_Data!F25 -> 2121 | B26: =Model_Data!E25 -> 33518.88 | C26: =Model_Data!I25 -> 88.5 | D26: =Model_Data!G25 -> 0.176 | E26: =Model_Data!M25 -> 0 | F26: =Model_Data!N25 -> 0 | G26: =Model_Data!O25 -> 1 | H26: =Model_Data!S25 -> 491905.13
A27: =Model_Data!F26 -> 3364 | B27: =Model_Data!E26 -> 42267.37 | C27: =Model_Data!I26 -> 82 | D27: =Model_Data!G26 -> 0.16 | E27: =Model_Data!M26 -> 0 | F27: =Model_Data!N26 -> 0 | G27: =Model_Data!O26 -> 1 | H27: =Model_Data!S26 -> 555929.4
A28: =Model_Data!F27 -> 2613 | B28: =Model_Data!E27 -> 62060.43 | C28: =Model_Data!I27 -> 92.1 | D28: =Model_Data!G27 -> 0.216 | E28: =Model_Data!M27 -> 0 | F28: =Model_Data!N27 -> 0 | G28: =Model_Data!O27 -> 1 | H28: =Model_Data!S27 -> 565810.99
A29: =Model_Data!F28 -> 10218 | B29: =Model_Data!E28 -> 57696.69 | C29: =Model_Data!I28 -> 94.8 | D29: =Model_Data!G28 -> 0.121 | E29: =Model_Data!M28 -> 0 | F29: =Model_Data!N28 -> 1 | G29: =Model_Data!O28 -> 0 | H29: =Model_Data!S28 -> 811771.14
A30: =Model_Data!F29 -> 8927 | B30: =Model_Data!E29 -> 172415.52 | C30: =Model_Data!I29 -> 86.2 | D30: =Model_Data!G29 -> 0.14 | E30: =Model_Data!M29 -> 0 | F30: =Model_Data!N29 -> 1 | G30: =Model_Data!O29 -> 0 | H30: =Model_Data!S29 -> 800451.94
A31: =Model_Data!F30 -> 9315 | B31: =Model_Data!E30 -> 55270.52 | C31: =Model_Data!I30 -> 91.9 | D31: =Model_Data!G30 -> 0.169 | E31: =Model_Data!M30 -> 0 | F31: =Model_Data!N30 -> 1 | G31: =Model_Data!O30 -> 0 | H31: =Model_Data!S30 -> 783672.82
A32: =Model_Data!F31 -> 7223 | B32: =Model_Data!E31 -> 52715.1 | C32: =Model_Data!I31 -> 84.2 | D32: =Model_Data!G31 -> 0.122 | E32: =Model_Data!M31 -> 0 | F32: =Model_Data!N31 -> 1 | G32: =Model_Data!O31 -> 0 | H32: =Model_Data!S31 -> 701641.97
A33: =Model_Data!F32 -> 3988 | B33: =Model_Data!E32 -> 68600.62 | C33: =Model_Data!I32 -> 85 | D33: =Model_Data!G32 -> 0.124 | E33: =Model_Data!M32 -> 0 | F33: =Model_Data!N32 -> 0 | G33: =Model_Data!O32 -> 1 | H33: =Model_Data!S32 -> 511844.41
A34: =Model_Data!F33 -> 2390 | B34: =Model_Data!E33 -> 63176.73 | C34: =Model_Data!I33 -> 87.5 | D34: =Model_Data!G33 -> 0.216 | E34: =Model_Data!M33 -> 0 | F34: =Model_Data!N33 -> 0 | G34: =Model_Data!O33 -> 1 | H34: =Model_Data!S33 -> 537383.79
A35: =Model_Data!F34 -> 2471 | B35: =Model_Data!E34 -> 44970.08 | C35: =Model_Data!I34 -> 87.6 | D35: =Model_Data!G34 -> 0.136 | E35: =Model_Data!M34 -> 0 | F35: =Model_Data!N34 -> 0 | G35: =Model_Data!O34 -> 1 | H35: =Model_Data!S34 -> 500173.02
A36: =Model_Data!F35 -> 971 | B36: =Model_Data!E35 -> 69816.35 | C36: =Model_Data!I35 -> 89.9 | D36: =Model_Data!G35 -> 0.168 | E36: =Model_Data!M35 -> 0 | F36: =Model_Data!N35 -> 0 | G36: =Model_Data!O35 -> 1 | H36: =Model_Data!S35 -> 427917.38
... A324: =Model_Data!F323 -> 5317 | B324: =Model_Data!E323 -> 40553.11 | C324: =Model_Data!I323 -> 84.3 | D324: =Model_Data!G323 -> 0.165 | E324: =Model_Data!M323 -> 0 | F324: =Model_Data!N323 -> 0 | G324: =Model_Data!O323 -> 1 | H324: =Model_Data!S323 -> 559660.84

Sheet Predictions_Residuals
A1: Predicted Sales & Residuals (Final Model = Multiple Regression)
A2: predicted_sales = Intercept + sum(coefficient_i * value_i); residual = monthly_sales - predicted_sales
A4: store_id | B4: month | C4: region | D4: store_type | E4: monthly_sales | F4: predicted_sales | G4: residual | H4: abs_residual | J4: Top 5 Largest POSITIVE Residuals (model under-predicts)
A5: =Model_Data!A4 -> STR-1001 | B5: =Model_Data!B4 -> 45658 | C5: =Model_Data!C4 -> East | D5: =Model_Data!D4 -> Residential | E5: =Multiple_Regression!H5 -> 658832.62 | F5: =Multiple_Regression!$L$12+Multiple_Regression!$L$13*Multiple_Regression!A5+Multiple_Regression!$L$14*Multiple_Regression!B5+Multiple_Regression!$L$15*Multiple_Regression!C5+Multiple_Regression!$L$16*Multiple_Regression!D5+Multiple_Regression!$L$17*Multiple_Regression!E5+Multiple_Regression!$L$18*Multiple_Regression!F5+Multiple_Regression!$L$19*Multiple_Regression!G5 -> 704472.7 | G5: =E5-F5 -> -45640.084 | H5: =ABS(G5) -> 45640.084 | J5: Rank | K5: store_id | L5: region | M5: store_type | N5: Residual
A6: =Model_Data!A5 -> STR-1001 | B6: =Model_Data!B5 -> 45689 | C6: =Model_Data!C5 -> East | D6: =Model_Data!D5 -> Residential | E6: =Multiple_Regression!H6 -> 634436 | F6: =Multiple_Regression!$L$12+Multiple_Regression!$L$13*Multiple_Regression!A6+Multiple_Regression!$L$14*Multiple_Regression!B6+Multiple_Regression!$L$15*Multiple_Regression!C6+Multiple_Regression!$L$16*Multiple_Regression!D6+Multiple_Regression!$L$17*Multiple_Regression!E6+Multiple_Regression!$L$18*Multiple_Regression!F6+Multiple_Regression!$L$19*Multiple_Regression!G6 -> 700530.92 | G6: =E6-F6 -> -66094.922 | H6: =ABS(G6) -> 66094.922 | J6: 1 | K6: =INDEX($A$5:$A$324,MATCH(N6,$G$5:$G$324,0)) -> STR-1030 | L6: =INDEX($C$5:$C$324,MATCH(N6,$G$5:$G$324,0)) -> West | M6: =INDEX($D$5:$D$324,MATCH(N6,$G$5:$G$324,0)) -> Residential | N6: =LARGE($G$5:$G$324,1) -> 105899.45
A7: =Model_Data!A6 -> STR-1001 | B7: =Model_Data!B6 -> 45717 | C7: =Model_Data!C6 -> East | D7: =Model_Data!D6 -> Residential | E7: =Multiple_Regression!H7 -> 678722.06 | F7: =Multiple_Regression!$L$12+Multiple_Regression!$L$13*Multiple_Regression!A7+Multiple_Regression!$L$14*Multiple_Regression!B7+Multiple_Regression!$L$15*Multiple_Regression!C7+Multiple_Regression!$L$16*Multiple_Regression!D7+Multiple_Regression!$L$17*Multiple_Regression!E7+Multiple_Regression!$L$18*Multiple_Regression!F7+Multiple_Regression!$L$19*Multiple_Regression!G7 -> 753228.65 | G7: =E7-F7 -> -74506.593 | H7: =ABS(G7) -> 74506.593 | J7: 2 | K7: =INDEX($A$5:$A$324,MATCH(N7,$G$5:$G$324,0)) -> STR-1073 | L7: =INDEX($C$5:$C$324,MATCH(N7,$G$5:$G$324,0)) -> East | M7: =INDEX($D$5:$D$324,MATCH(N7,$G$5:$G$324,0)) -> Residential | N7: =LARGE($G$5:$G$324,2) -> 99623.41
A8: =Model_Data!A7 -> STR-1001 | B8: =Model_Data!B7 -> 45748 | C8: =Model_Data!C7 -> East | D8: =Model_Data!D7 -> Residential | E8: =Multiple_Regression!H8 -> 658920.3 | F8: =Multiple_Regression!$L$12+Multiple_Regression!$L$13*Multiple_Regression!A8+Multiple_Regression!$L$14*Multiple_Regression!B8+Multiple_Regression!$L$15*Multiple_Regression!C8+Multiple_Regression!$L$16*Multiple_Regression!D8+Multiple_Regression!$L$17*Multiple_Regression!E8+Multiple_Regression!$L$18*Multiple_Regression!F8+Multiple_Regression!$L$19*Multiple_Regression!G8 -> 756529.96 | G8: =E8-F8 -> -97609.655 | H8: =ABS(G8) -> 97609.655 | J8: 3 | K8: =INDEX($A$5:$A$324,MATCH(N8,$G$5:$G$324,0)) -> STR-1032 | L8: =INDEX($C$5:$C$324,MATCH(N8,$G$5:$G$324,0)) -> South | M8: =INDEX($D$5:$D$324,MATCH(N8,$G$5:$G$324,0)) -> High Street | N8: =LARGE($G$5:$G$324,3) -> 98771.441
A9: =Model_Data!A8 -> STR-1002 | B9: =Model_Data!B8 -> 45658 | C9: =Model_Data!C8 -> East | D9: =Model_Data!D8 -> High Street | E9: =Multiple_Regression!H9 -> 741341.44 | F9: =Multiple_Regression!$L$12+Multiple_Regression!$L$13*Multiple_Regression!A9+Multiple_Regression!$L$14*Multiple_Regression!B9+Multiple_Regression!$L$15*Multiple_Regression!C9+Multiple_Regression!$L$16*Multiple_Regression!D9+Multiple_Regression!$L$17*Multiple_Regression!E9+Multiple_Regression!$L$18*Multiple_Regression!F9+Multiple_Regression!$L$19*Multiple_Regression!G9 -> 793970.98 | G9: =E9-F9 -> -52629.537 | H9: =ABS(G9) -> 52629.537 | J9: 4 | K9: =INDEX($A$5:$A$324,MATCH(N9,$G$5:$G$324,0)) -> STR-1050 | L9: =INDEX($C$5:$C$324,MATCH(N9,$G$5:$G$324,0)) -> North | M9: =INDEX($D$5:$D$324,MATCH(N9,$G$5:$G$324,0)) -> Residential | N9: =LARGE($G$5:$G$324,4) -> 97246.493
A10: =Model_Data!A9 -> STR-1002 | B10: =Model_Data!B9 -> 45689 | C10: =Model_Data!C9 -> East | D10: =Model_Data!D9 -> High Street | E10: =Multiple_Regression!H10 -> 761835.34 | F10: =Multiple_Regression!$L$12+Multiple_Regression!$L$13*Multiple_Regression!A10+Multiple_Regression!$L$14*Multiple_Regression!B10+Multiple_Regression!$L$15*Multiple_Regression!C10+Multiple_Regression!$L$16*Multiple_Regression!D10+Multiple_Regression!$L$17*Multiple_Regression!E10+Multiple_Regression!$L$18*Multiple_Regression!F10+Multiple_Regression!$L$19*Multiple_Regression!G10 -> 788194.06 | G10: =E10-F10 -> -26358.716 | H10: =ABS(G10) -> 26358.716 | J10: 5 | K10: =INDEX($A$5:$A$324,MATCH(N10,$G$5:$G$324,0)) -> STR-1028 | L10: =INDEX($C$5:$C$324,MATCH(N10,$G$5:$G$324,0)) -> East | M10: =INDEX($D$5:$D$324,MATCH(N10,$G$5:$G$324,0)) -> Mall | N10: =LARGE($G$5:$G$324,5) -> 95145.324
A11: =Model_Data!A10 -> STR-1002 | B11: =Model_Data!B10 -> 45717 | C11: =Model_Data!C10 -> East | D11: =Model_Data!D10 -> High Street | E11: =Multiple_Regression!H11 -> 806615.54 | F11: =Multiple_Regression!$L$12+Multiple_Regression!$L$13*Multiple_Regression!A11+Multiple_Regression!$L$14*Multiple_Regression!B11+Multiple_Regression!$L$15*Multiple_Regression!C11+Multiple_Regression!$L$16*Multiple_Regression!D11+Multiple_Regression!$L$17*Multiple_Regression!E11+Multiple_Regression!$L$18*Multiple_Regression!F11+Multiple_Regression!$L$19*Multiple_Regression!G11 -> 796669.96 | G11: =E11-F11 -> 9945.5847 | H11: =ABS(G11) -> 9945.5847
A12: =Model_Data!A11 -> STR-1002 | B12: =Model_Data!B11 -> 45748 | C12: =Model_Data!C11 -> East | D12: =Model_Data!D11 -> High Street | E12: =Multiple_Regression!H12 -> 850164.26 | F12: =Multiple_Regression!$L$12+Multiple_Regression!$L$13*Multiple_Regression!A12+Multiple_Regression!$L$14*Multiple_Regression!B12+Multiple_Regression!$L$15*Multiple_Regression!C12+Multiple_Regression!$L$16*Multiple_Regression!D12+Multiple_Regression!$L$17*Multiple_Regression!E12+Multiple_Regression!$L$18*Multiple_Regression!F12+Multiple_Regression!$L$19*Multiple_Regression!G12 -> 784174.59 | G12: =E12-F12 -> 65989.67 | H12: =ABS(G12) -> 65989.67
A13: =Model_Data!A12 -> STR-1003 | B13: =Model_Data!B12 -> 45658 | C13: =Model_Data!C12 -> North | D13: =Model_Data!D12 -> Airport | E13: =Multiple_Regression!H13 -> 930581.7 | F13: =Multiple_Regression!$L$12+Multiple_Regression!$L$13*Multiple_Regression!A13+Multiple_Regression!$L$14*Multiple_Regression!B13+Multiple_Regression!$L$15*Multiple_Regression!C13+Multiple_Regression!$L$16*Multiple_Regression!D13+Multiple_Regression!$L$17*Multiple_Regression!E13+Multiple_Regression!$L$18*Multiple_Regression!F13+Multiple_Regression!$L$19*Multiple_Regression!G13 -> 865386.51 | G13: =E13-F13 -> 65195.186 | H13: =ABS(G13) -> 65195.186 | J13: Top 5 Largest NEGATIVE Residuals (model over-predicts)
A14: =Model_Data!A13 -> STR-1003 | B14: =Model_Data!B13 -> 45689 | C14: =Model_Data!C13 -> North | D14: =Model_Data!D13 -> Airport | E14: =Multiple_Regression!H14 -> 779010.94 | F14: =Multiple_Regression!$L$12+Multiple_Regression!$L$13*Multiple_Regression!A14+Multiple_Regression!$L$14*Multiple_Regression!B14+Multiple_Regression!$L$15*Multiple_Regression!C14+Multiple_Regression!$L$16*Multiple_Regression!D14+Multiple_Regression!$L$17*Multiple_Regression!E14+Multiple_Regression!$L$18*Multiple_Regression!F14+Multiple_Regression!$L$19*Multiple_Regression!G14 -> 798799.07 | G14: =E14-F14 -> -19788.129 | H14: =ABS(G14) -> 19788.129 | J14: Rank | K14: store_id | L14: region | M14: store_type | N14: Residual
A15: =Model_Data!A14 -> STR-1003 | B15: =Model_Data!B14 -> 45717 | C15: =Model_Data!C14 -> North | D15: =Model_Data!D14 -> Airport | E15: =Multiple_Regression!H15 -> 723060.76 | F15: =Multiple_Regression!$L$12+Multiple_Regression!$L$13*Multiple_Regression!A15+Multiple_Regression!$L$14*Multiple_Regression!B15+Multiple_Regression!$L$15*Multiple_Regression!C15+Multiple_Regression!$L$16*Multiple_Regression!D15+Multiple_Regression!$L$17*Multiple_Regression!E15+Multiple_Regression!$L$18*Multiple_Regression!F15+Multiple_Regression!$L$19*Multiple_Regression!G15 -> 760003.9 | G15: =E15-F15 -> -36943.143 | H15: =ABS(G15) -> 36943.143 | J15: 1 | K15: =INDEX($A$5:$A$324,MATCH(N15,$G$5:$G$324,0)) -> STR-1017 | L15: =INDEX($C$5:$C$324,MATCH(N15,$G$5:$G$324,0)) -> West | M15: =INDEX($D$5:$D$324,MATCH(N15,$G$5:$G$324,0)) -> High Street | N15: =SMALL($G$5:$G$324,1) -> -159241.23
A16: =Model_Data!A15 -> STR-1003 | B16: =Model_Data!B15 -> 45748 | C16: =Model_Data!C15 -> North | D16: =Model_Data!D15 -> Airport | E16: =Multiple_Regression!H16 -> 910791.94 | F16: =Multiple_Regression!$L$12+Multiple_Regression!$L$13*Multiple_Regression!A16+Multiple_Regression!$L$14*Multiple_Regression!B16+Multiple_Regression!$L$15*Multiple_Regression!C16+Multiple_Regression!$L$16*Multiple_Regression!D16+Multiple_Regression!$L$17*Multiple_Regression!E16+Multiple_Regression!$L$18*Multiple_Regression!F16+Multiple_Regression!$L$19*Multiple_Regression!G16 -> 871984.85 | G16: =E16-F16 -> 38807.089 | H16: =ABS(G16) -> 38807.089 | J16: 2 | K16: =INDEX($A$5:$A$324,MATCH(N16,$G$5:$G$324,0)) -> STR-1023 | L16: =INDEX($C$5:$C$324,MATCH(N16,$G$5:$G$324,0)) -> South | M16: =INDEX($D$5:$D$324,MATCH(N16,$G$5:$G$324,0)) -> Mall | N16: =SMALL($G$5:$G$324,2) -> -128265.26
A17: =Model_Data!A16 -> STR-1004 | B17: =Model_Data!B16 -> 45658 | C17: =Model_Data!C16 -> East | D17: =Model_Data!D16 -> Residential | E17: =Multiple_Regression!H17 -> 922168.6 | F17: =Multiple_Regression!$L$12+Multiple_Regression!$L$13*Multiple_Regression!A17+Multiple_Regression!$L$14*Multiple_Regression!B17+Multiple_Regression!$L$15*Multiple_Regression!C17+Multiple_Regression!$L$16*Multiple_Regression!D17+Multiple_Regression!$L$17*Multiple_Regression!E17+Multiple_Regression!$L$18*Multiple_Regression!F17+Multiple_Regression!$L$19*Multiple_Regression!G17 -> 872478.78 | G17: =E17-F17 -> 49689.822 | H17: =ABS(G17) -> 49689.822 | J17: 3 | K17: =INDEX($A$5:$A$324,MATCH(N17,$G$5:$G$324,0)) -> STR-1012 | L17: =INDEX($C$5:$C$324,MATCH(N17,$G$5:$G$324,0)) -> West | M17: =INDEX($D$5:$D$324,MATCH(N17,$G$5:$G$324,0)) -> Residential | N17: =SMALL($G$5:$G$324,3) -> -121078.89
A18: =Model_Data!A17 -> STR-1004 | B18: =Model_Data!B17 -> 45689 | C18: =Model_Data!C17 -> East | D18: =Model_Data!D17 -> Residential | E18: =Multiple_Regression!H18 -> 726606.28 | F18: =Multiple_Regression!$L$12+Multiple_Regression!$L$13*Multiple_Regression!A18+Multiple_Regression!$L$14*Multiple_Regression!B18+Multiple_Regression!$L$15*Multiple_Regression!C18+Multiple_Regression!$L$16*Multiple_Regression!D18+Multiple_Regression!$L$17*Multiple_Regression!E18+Multiple_Regression!$L$18*Multiple_Regression!F18+Multiple_Regression!$L$19*Multiple_Regression!G18 -> 769936.36 | G18: =E18-F18 -> -43330.085 | H18: =ABS(G18) -> 43330.085 | J18: 4 | K18: =INDEX($A$5:$A$324,MATCH(N18,$G$5:$G$324,0)) -> STR-1007 | L18: =INDEX($C$5:$C$324,MATCH(N18,$G$5:$G$324,0)) -> West | M18: =INDEX($D$5:$D$324,MATCH(N18,$G$5:$G$324,0)) -> Mall | N18: =SMALL($G$5:$G$324,4) -> -99820.541
A19: =Model_Data!A18 -> STR-1004 | B19: =Model_Data!B18 -> 45717 | C19: =Model_Data!C18 -> East | D19: =Model_Data!D18 -> Residential | E19: =Multiple_Regression!H19 -> 746501.09 | F19: =Multiple_Regression!$L$12+Multiple_Regression!$L$13*Multiple_Regression!A19+Multiple_Regression!$L$14*Multiple_Regression!B19+Multiple_Regression!$L$15*Multiple_Regression!C19+Multiple_Regression!$L$16*Multiple_Regression!D19+Multiple_Regression!$L$17*Multiple_Regression!E19+Multiple_Regression!$L$18*Multiple_Regression!F19+Multiple_Regression!$L$19*Multiple_Regression!G19 -> 742679.03 | G19: =E19-F19 -> 3822.0632 | H19: =ABS(G19) -> 3822.0632 | J19: 5 | K19: =INDEX($A$5:$A$324,MATCH(N19,$G$5:$G$324,0)) -> STR-1009 | L19: =INDEX($C$5:$C$324,MATCH(N19,$G$5:$G$324,0)) -> North | M19: =INDEX($D$5:$D$324,MATCH(N19,$G$5:$G$324,0)) -> Residential | N19: =SMALL($G$5:$G$324,5) -> -98450.319
A20: =Model_Data!A19 -> STR-1004 | B20: =Model_Data!B19 -> 45748 | C20: =Model_Data!C19 -> East | D20: =Model_Data!D19 -> Residential | E20: =Multiple_Regression!H20 -> 834017.02 | F20: =Multiple_Regression!$L$12+Multiple_Regression!$L$13*Multiple_Regression!A20+Multiple_Regression!$L$14*Multiple_Regression!B20+Multiple_Regression!$L$15*Multiple_Regression!C20+Multiple_Regression!$L$16*Multiple_Regression!D20+Multiple_Regression!$L$17*Multiple_Regression!E20+Multiple_Regression!$L$18*Multiple_Regression!F20+Multiple_Regression!$L$19*Multiple_Regression!G20 -> 805632.61 | G20: =E20-F20 -> 28384.411 | H20: =ABS(G20) -> 28384.411
A21: =Model_Data!A20 -> STR-1005 | B21: =Model_Data!B20 -> 45658 | C21: =Model_Data!C20 -> South | D21: =Model_Data!D20 -> Residential | E21: =Multiple_Regression!H21 -> 666152.52 | F21: =Multiple_Regression!$L$12+Multiple_Regression!$L$13*Multiple_Regression!A21+Multiple_Regression!$L$14*Multiple_Regression!B21+Multiple_Regression!$L$15*Multiple_Regression!C21+Multiple_Regression!$L$16*Multiple_Regression!D21+Multiple_Regression!$L$17*Multiple_Regression!E21+Multiple_Regression!$L$18*Multiple_Regression!F21+Multiple_Regression!$L$19*Multiple_Regression!G21 -> 677698.74 | G21: =E21-F21 -> -11546.218 | H21: =ABS(G21) -> 11546.218
A22: =Model_Data!A21 -> STR-1005 | B22: =Model_Data!B21 -> 45689 | C22: =Model_Data!C21 -> South | D22: =Model_Data!D21 -> Residential | E22: =Multiple_Regression!H22 -> 573155.19 | F22: =Multiple_Regression!$L$12+Multiple_Regression!$L$13*Multiple_Regression!A22+Multiple_Regression!$L$14*Multiple_Regression!B22+Multiple_Regression!$L$15*Multiple_Regression!C22+Multiple_Regression!$L$16*Multiple_Regression!D22+Multiple_Regression!$L$17*Multiple_Regression!E22+Multiple_Regression!$L$18*Multiple_Regression!F22+Multiple_Regression!$L$19*Multiple_Regression!G22 -> 588643.82 | G22: =E22-F22 -> -15488.63 | H22: =ABS(G22) -> 15488.63
A23: =Model_Data!A22 -> STR-1005 | B23: =Model_Data!B22 -> 45717 | C23: =Model_Data!C22 -> South | D23: =Model_Data!D22 -> Residential | E23: =Multiple_Regression!H23 -> 666573.2 | F23: =Multiple_Regression!$L$12+Multiple_Regression!$L$13*Multiple_Regression!A23+Multiple_Regression!$L$14*Multiple_Regression!B23+Multiple_Regression!$L$15*Multiple_Regression!C23+Multiple_Regression!$L$16*Multiple_Regression!D23+Multiple_Regression!$L$17*Multiple_Regression!E23+Multiple_Regression!$L$18*Multiple_Regression!F23+Multiple_Regression!$L$19*Multiple_Regression!G23 -> 681060.9 | G23: =E23-F23 -> -14487.703 | H23: =ABS(G23) -> 14487.703
